Workbook

Sheet Forecast Drivers
B2: Actual | C2: Forecast
A3: Operating Drivers | B3: Year 0 | C3: Year 1 | D3: Year 2 | E3: Year 3 | F3: Year 4
A4: Revenue growth rate | C4: 0.4 | D4: 0.3 | E4: 0.2 | F4: 0.1
A5: Cost of goods sold (% of revenues) | B5: 0.6 | C5: 0.6 | D5: 0.6 | E5: 0.6 | F5: 0.6
A6: Depreciation (# of years, straight-line basis) | B6: 10 | C6: 10 | D6: 10 | E6: 10 | F6: 10
A7: Constant income tax rate | B7: 0.3 | C7: 0.3 | D7: 0.3 | E7: 0.3 | F7: 0.3
A8: Cash (% of revenues) | B8: 0.1 | C8: 0.1 | D8: 0.1 | E8: 0.1 | F8: 0.1
A9: Accounts receivable (% of revenues) | B9: 0.2 | C9: 0.2 | D9: 0.2 | E9: 0.2 | F9: 0.2
A10: Capital expenditures | B10: 670 | C10: 700 | D10: 610 | E10: 360 | F10: 200
A11: Cost of debt | B11: 0.1 | C11: 0.1 | D11: 0.1 | E11: 0.1 | F11: 0.1

Sheet Financial Statements
A1: Income Statement
B2: Year 0 | C2: Year 1 | D2: Year 2 | E2: Year 3 | F2: Year 4
A3: Revenue | B3: 1000 | C3: =B3*(1+'Forecast Drivers'!C4) -> 1400 | D3: =C3*(1+'Forecast Drivers'!D4) -> 1820 | E3: =D3*(1+'Forecast Drivers'!E4) -> 2184 | F3: =E3*(1+'Forecast Drivers'!F4) -> 2402.4
A4: Cost of goods sold (COGS) | B4: 600 | C4: =C3*'Forecast Drivers'!C5 -> 840 | D4: =D3*'Forecast Drivers'!D5 -> 1092 | E4: =E3*'Forecast Drivers'!E5 -> 1310.4 | F4: =F3*'Forecast Drivers'!F5 -> 1441.44
A5: Depreciation | B5: 167 | C5: ='Plant and Equipment Schedule'!C8 -> 233.7 | D5: ='Plant and Equipment Schedule'!D8 -> 303.7 | E5: ='Plant and Equipment Schedule'!E8 -> 364.7 | F5: ='Plant and Equipment Schedule'!F8 -> 400.7
A6: Earnings before interest and taxes (EBIT) | B6: =B3-B4-B5 -> 233 | C6: =C3-C4-C5 -> 326.3 | D6: =D3-D4-D5 -> 424.3 | E6: =E3-E4-E5 -> 508.9 | F6: =F3-F4-F5 -> 560.26
A7: Interest expense | B7: 0 | C7: =B22*'Forecast Drivers'!C11 -> 0 | D7: =C22*'Forecast Drivers'!D11 -> 0 | E7: =D22*'Forecast Drivers'!E11 -> 0 | F7: =E22*'Forecast Drivers'!F11 -> 0
A8: Earnings before taxes (EBT) | B8: =B6-B7 -> 233 | C8: =C6-C7 -> 326.3 | D8: =D6-D7 -> 424.3 | E8: =E6-E7 -> 508.9 | F8: =F6-F7 -> 560.26
A9: Income tax expense | B9: =B8*'Forecast Drivers'!B7 -> 69.9 | C9: =C8*'Forecast Drivers'!C7 -> 97.89 | D9: =D8*'Forecast Drivers'!D7 -> 127.29 | E9: =E8*'Forecast Drivers'!E7 -> 152.67 | F9: =F8*'Forecast Drivers'!F7 -> 168.078
A10: Net Income | B10: =B8-B9 -> 163.1 | C10: =C8-C9 -> 228.41 | D10: =D8-D9 -> 297.01 | E10: =E8-E9 -> 356.23 | F10: =F8-F9 -> 392.182
A14: Balance Sheet
B15: Year 0 | C15: Year 1 | D15: Year 2 | E15: Year 3 | F15: Year 4
A16: Cash | B16: 100 | C16: =C3*'Forecast Drivers'!C8 -> 140 | D16: =D3*'Forecast Drivers'!D8 -> 182 | E16: =E3*'Forecast Drivers'!E8 -> 218.4 | F16: =F3*'Forecast Drivers'!F8 -> 240.24
A17: Accounts receivable | B17: 200 | C17: =C3*'Forecast Drivers'!C9 -> 280 | D17: =D3*'Forecast Drivers'!D9 -> 364 | E17: =E3*'Forecast Drivers'!E9 -> 436.8 | F17: =F3*'Forecast Drivers'!F9 -> 480.48
A18: Total current assets | B18: =B16+B17 -> 300 | C18: =C16+C17 -> 420 | D18: =D16+D17 -> 546 | E18: =E16+E17 -> 655.2 | F18: =F16+F17 -> 720.72
A19: Property, plant, and equipment (net) | B19: 1837 | C19: ='Plant and Equipment Schedule'!C11 -> 2303.3 | D19: ='Plant and Equipment Schedule'!D11 -> 2609.6 | E19: ='Plant and Equipment Schedule'!E11 -> 2604.9 | F19: ='Plant and Equipment Schedule'!F11 -> 2404.2
A20: Total assets | B20: =B18+B19 -> 2137 | C20: =C18+C19 -> 2723.3 | D20: =D18+D19 -> 3155.6 | E20: =E18+E19 -> 3260.1 | F20: =F18+F19 -> 3124.92
A22: Debt | B22: 0 | C22: =B22*(1+'Forecast Drivers'!C11)+C51-'Financial Statements'!C7 -> 0 | D22: =C22*(1+'Forecast Drivers'!D11)+D51-'Financial Statements'!D7 -> 0 | E22: =D22*(1+'Forecast Drivers'!E11)+E51-'Financial Statements'!E7 -> 0 | F22: =E22*(1+'Forecast Drivers'!F11)+F51-'Financial Statements'!F7 -> 0
A23: Capital stock | B23: 100 | C23: =B23+C52 -> 457.89 | D23: =C23+D52 -> 593.18 | E23: =D23+E52 -> 593.18 | F23: =E23+F52 -> 593.18
A24: Retained earnings | B24: 2037 | C24: =B24+(C32-C33) -> 2265.41 | D24: =C24+(D32-D33) -> 2562.42 | E24: =D24+(E32-E33) -> 2666.92 | F24: =E24+(F32-F33) -> 2531.74
A25: Liabilities and shareholders' equity | B25: =B22+B23+B24 -> 2137 | C25: =C22+C23+C24 -> 2723.3 | D25: =D22+D23+D24 -> 3155.6 | E25: =E22+E23+E24 -> 3260.1 | F25: =F22+F23+F24 -> 3124.92
A29: Statement of Retained Earnings
B30: Year 0 | C30: Year 1 | D30: Year 2 | E30: Year 3 | F30: Year 4
A31: Retained earnings -- Beginning of year | B31: 1873.9 | C31: =B34 -> 2037 | D31: =C34 -> 2265.41 | E31: =D34 -> 2562.42 | F31: =E34 -> 2666.92
A32: Net income | B32: =B10 -> 163.1 | C32: =C10 -> 228.41 | D32: =D10 -> 297.01 | E32: =E10 -> 356.23 | F32: =F10 -> 392.182
A33: Common equity dividends | B33: 0 | C33: =C53 -> 0 | D33: =D53 -> 0 | E33: =E53 -> 251.73 | F33: =F53 -> 527.362
A34: Retained earnings -- End of year | B34: =B31+B32-B33 -> 2037 | C34: =C31+C32-C33 -> 2265.41 | D34: =D31+D32-D33 -> 2562.42 | E34: =E31+E32-E33 -> 2666.92 | F34: =F31+F32-F33 -> 2531.74
A38: Cash Flow Statement
B39: Year 0 | C39: Year 1 | D39: Year 2 | E39: Year 3 | F39: Year 4
A40: Cash flows from operations
A41: Net income | B41: =B10 -> 163.1 | C41: =C10 -> 228.41 | D41: =D10 -> 297.01 | E41: =E10 -> 356.23 | F41: =F10 -> 392.182
A42: + Depreciation expense | B42: =B5 -> 167 | C42: =C5 -> 233.7 | D42: =D5 -> 303.7 | E42: =E5 -> 364.7 | F42: =F5 -> 400.7
A43: - Change in accounts receivable | B43: 20 | C43: =C17-B17 -> 80 | D43: =D17-C17 -> 84 | E43: =E17-D17 -> 72.8 | F43: =F17-E17 -> 43.68
A44: Cash flow from operations | B44: =B41+B42-B43 -> 310.1 | C44: =C41+C42-C43 -> 382.11 | D44: =D41+D42-D43 -> 516.71 | E44: =E41+E42-E43 -> 648.13 | F44: =F41+F42-F43 -> 749.202
A46: Investing activities
A47: - Capital expenditures | B47: 670 | C47: ='Plant and Equipment Schedule'!C4 -> 700 | D47: ='Plant and Equipment Schedule'!D4 -> 610 | E47: ='Plant and Equipment Schedule'!E4 -> 360 | F47: ='Plant and Equipment Schedule'!F4 -> 200
A48: Cash flow from investing actitivies | B48: =-B47 -> -670 | C48: =-C47 -> -700 | D48: =-D47 -> -610 | E48: =-E47 -> -360 | F48: =-F47 -> -200
A50: Financing activities
A51: + Change in debt financing | B51: 0 | C51: 0 | D51: 0 | E51: 0 | F51: 0
A52: + Change in common equity financing | B52: 0 | C52: =IF(C54>0,C54,0) -> 357.89 | D52: =IF(D54>0,D54,0) -> 135.29 | E52: =IF(E54>0,E54,0) -> 0 | F52: =IF(F54>0,F54,0) -> 0
...

Sheet Plant and Equipment Schedule
A1: Plant and Equipment (PPEQ) Schedule
B2: Year 0 | C2: Year 1 | D2: Year 2 | E2: Year 3 | F2: Year 4
A3: Beginning PPEQ -- gross | B3: 1667 | C3: =B5 -> 2337 | D3: =C5 -> 3037 | E3: =D5 -> 3647 | F3: =E5 -> 4007
A4: Capital expenditures | B4: 670 | C4: ='Forecast Drivers'!C10 -> 700 | D4: ='Forecast Drivers'!D10 -> 610 | E4: ='Forecast Drivers'!E10 -> 360 | F4: ='Forecast Drivers'!F10 -> 200
A5: Ending PPEQ -- gross | B5: =B3+B4 -> 2337 | C5: =C3+C4 -> 3037 | D5: =D3+D4 -> 3647 | E5: =E3+E4 -> 4007 | F5: =F3+F4 -> 4207
A7: Beginning accumulated depreciation | B7: 333 | C7: =B9 -> 500 | D7: =C9 -> 733.7 | E7: =D9 -> 1037.4 | F7: =E9 -> 1402.1
A8: Depreciation expense | B8: 167 | C8: =C3/'Forecast Drivers'!C6 -> 233.7 | D8: =D3/'Forecast Drivers'!D6 -> 303.7 | E8: =E3/'Forecast Drivers'!E6 -> 364.7 | F8: =F3/'Forecast Drivers'!F6 -> 400.7
A9: Ending accumulated depreciation | B9: =B7+B8 -> 500 | C9: =C7+C8 -> 733.7 | D9: =D7+D8 -> 1037.4 | E9: =E7+E8 -> 1402.1 | F9: =F7+F8 -> 1802.8
A11: Net property, plant, and equipment | B11: =B5-B9 -> 1837 | C11: =C5-C9 -> 2303.3 | D11: =D5-D9 -> 2609.6 | E11: =E5-E9 -> 2604.9 | F11: =F5-F9 -> 2404.2
A14: Black cells = assumptions
A15: Blue cells = equations

Sheet FCF Schedule
A1: FCF Schedule
B2: Year 0 | C2: Year 1 | D2: Year 2 | E2: Year 3 | F2: Year 4
A3: Operating cash flows
A4: EBIT * (1 - T) | B4: =(1 - 'Forecast Drivers'!B7)*'Financial Statements'!B6 -> 163.1 | C4: =(1 - 'Forecast Drivers'!C7)*'Financial Statements'!C6 -> 228.41 | D4: =(1 - 'Forecast Drivers'!D7)*'Financial Statements'!D6 -> 297.01 | E4: =(1 - 'Forecast Drivers'!E7)*'Financial Statements'!E6 -> 356.23 | F4: =(1 - 'Forecast Drivers'!F7)*'Financial Statements'!F6 -> 392.182
A5: + Depreciation expense | B5: ='Financial Statements'!B5 -> 167 | C5: ='Financial Statements'!C5 -> 233.7 | D5: ='Financial Statements'!D5 -> 303.7 | E5: ='Financial Statements'!E5 -> 364.7 | F5: ='Financial Statements'!F5 -> 400.7
A6: Operating cash flows | B6: =B4+B5 -> 330.1 | C6: =C4+C5 -> 462.11 | D6: =D4+D5 -> 600.71 | E6: =E4+E5 -> 720.93 | F6: =F4+F5 -> 792.882
A8: Net capital spending
A9: Capital expenditures | B9: ='Plant and Equipment Schedule'!B4 -> 670 | C9: ='Plant and Equipment Schedule'!C4 -> 700 | D9: ='Plant and Equipment Schedule'!D4 -> 610 | E9: ='Plant and Equipment Schedule'!E4 -> 360 | F9: ='Plant and Equipment Schedule'!F4 -> 200
A10: Net capital spending | B10: =B9 -> 670 | C10: =C9 -> 700 | D10: =D9 -> 610 | E10: =E9 -> 360 | F10: =F9 -> 200
A12: Change in net working capital
A13: + Change in accounts receivable | B13: ='Financial Statements'!B43 -> 20 | C13: ='Financial Statements'!C43 -> 80 | D13: ='Financial Statements'!D43 -> 84 | E13: ='Financial Statements'!E43 -> 72.8 | F13: ='Financial Statements'!F43 -> 43.68
A14: + Change in cash | B14: 50 | C14: ='Financial Statements'!C56 -> 40 | D14: ='Financial Statements'!D56 -> 42 | E14: ='Financial Statements'!E56 -> 36.4 | F14: ='Financial Statements'!F56 -> 21.84
A15: Change in net working capital | B15: =B13+B14 -> 70 | C15: =C13+C14 -> 120 | D15: =D13+D14 -> 126 | E15: =E13+E14 -> 109.2 | F15: =F13+F14 -> 65.52
A17: FCF (OCF - NCS - Change in NWC) | B17: =B6-B10-B15 -> -409.9 | C17: =C6-C10-C15 -> -357.89 | D17: =D6-D10-D15 -> -135.29 | E17: =E6-E10-E15 -> 251.73 | F17: =F6-F10-F15 -> 527.362
A20: Black cells = assumptions
A21: Blue cells = equations

Sheet Reasonableness checks
A1: Projected financial ratios
B2: Year 0 | C2: Year 1 | D2: Year 2 | E2: Year 3 | F2: Year 4
A3: Asset use or efficiency ratios
A4: Asset turnover ratio | B4: ='Financial Statements'!B3/'Financial Statements'!B20 -> 0.46794572 | C4: ='Financial Statements'!C3/'Financial Statements'!C20 -> 0.51408218 | D4: ='Financial Statements'!D3/'Financial Statements'!D20 -> 0.57675244 | E4: ='Financial Statements'!E3/'Financial Statements'!E20 -> 0.6699181 | F4: ='Financial Statements'!F3/'Financial Statements'!F20 -> 0.76878768
A5: Fixed asset turnover ratio | B5: ='Financial Statements'!B3/'Financial Statements'!B19 -> 0.54436581 | C5: ='Financial Statements'!C3/'Financial Statements'!C19 -> 0.60782356 | D5: ='Financial Statements'!D3/'Financial Statements'!D19 -> 0.69742489 | E5: ='Financial Statements'!E3/'Financial Statements'!E19 -> 0.8384199 | F5: ='Financial Statements'!F3/'Financial Statements'!F19 -> 0.99925131
A7: Profitability measures
A8: Profit margin | B8: ='Financial Statements'!B10/'Financial Statements'!B3 -> 0.1631 | C8: ='Financial Statements'!C10/'Financial Statements'!C3 -> 0.16315 | D8: ='Financial Statements'!D10/'Financial Statements'!D3 -> 0.16319231 | E8: ='Financial Statements'!E10/'Financial Statements'!E3 -> 0.16310897 | F8: ='Financial Statements'!F10/'Financial Statements'!F3 -> 0.16324592
A9: Return on assets | B9: ='Financial Statements'!B10/'Financial Statements'!B20 -> 0.076321947 | C9: ='Financial Statements'!C10/'Financial Statements'!C20 -> 0.083872508 | D9: ='Financial Statements'!D10/'Financial Statements'!D20 -> 0.094121562 | E9: ='Financial Statements'!E10/'Financial Statements'!E20 -> 0.10926965 | F9: ='Financial Statements'!F10/'Financial Statements'!F20 -> 0.12550145
A10: Return on equity | B10: ='Financial Statements'!B10/'Financial Statements'!B23 -> 1.631 | C10: ='Financial Statements'!C10/'Financial Statements'!C23 -> 0.4988316 | D10: ='Financial Statements'!D10/'Financial Statements'!D23 -> 0.50070805 | E10: ='Financial Statements'!E10/'Financial Statements'!E23 -> 0.60054284 | F10: ='Financial Statements'!F10/'Financial Statements'!F23 -> 0.66115176
A12: Expense ratios
A13: Capex to revenues ratio | B13: ='Plant and Equipment Schedule'!B4/'Financial Statements'!B3 -> 0.67 | C13: ='Plant and Equipment Schedule'!C4/'Financial Statements'!C3 -> 0.5 | D13: ='Plant and Equipment Schedule'!D4/'Financial Statements'!D3 -> 0.33516484 | E13: ='Plant and Equipment Schedule'!E4/'Financial Statements'!E3 -> 0.16483516 | F13: ='Plant and Equipment Schedule'!F4/'Financial Statements'!F3 -> 0.083250083
A15: Growth rates and miscellaneous
A16: Growth rate of FCF (%) | C16: =IF('FCF Schedule'!B17>0,('FCF Schedule'!C17-'FCF Schedule'!B17)/'FCF Schedule'!B17*100,"n/a") -> n/a | D16: =IF('FCF Schedule'!C17>0,('FCF Schedule'!D17-'FCF Schedule'!C17)/'FCF Schedule'!C17*100,"n/a") -> n/a | E16: =IF('FCF Schedule'!D17>0,('FCF Schedule'!E17-'FCF Schedule'!D17)/'FCF Schedule'!D17*100,"n/a") -> n/a | F16: =IF('FCF Schedule'!E17>0,('FCF Schedule'!F17-'FCF Schedule'!E17)/'FCF Schedule'!E17*100,"n/a") -> 109.49509
A19: Blue cells = equations
